Workbook

Sheet Pledges
A1: Masjid Fundraiser — Pledge & Collection Tracker
A2: Yellow cells are for entry; green figures roll up from the Payments tab. Hover a column heading for an example. To add a donor, just type on the first empty row — the list grows on its own.
C3: Totals → | D3: =SUM($D$5:$D$2500) -> 0 | F3: =SUM($F$5:$F$2500) -> 0 | G3: =SUMIF($G$5:$G$2500,">0") -> 0 | H3: =SUM($H$5:$H$2500) -> 0
A4: Phone Number (Donor ID) | B4: Donor Name | C4: Date Pledged | D4: Amount Pledged ($) | E4: Last Payment Date | F4: Amount Received ($) | G4: Balance Due ($) | H4: # Payments | I4: Status | J4: Notes | K4: Match Key
E5: =IF(OR($D5="",$K5=""),"",IF(COUNTIFS(Payments!$G$5:$G$2500,$K5,Payments!$C$5:$C$2500,"<>")=0,"",_xlfn.MAXIFS(Payments!$C$5:$C$2500,Payments!$G$5:$G$2500,$K5))) | F5: =IF(OR($D5="",$K5=""),"",SUMIF(Payments!$G$5:$G$2500,$K5,Payments!$D$5:$D$2500)) | G5: =IF($D5="","",ROUND($D5-IF($F5="",0,$F5),2)) | H5: =IF(OR($D5="",$K5=""),"",COUNTIF(Payments!$G$5:$G$2500,$K5)) | I5: =IF($D5="","",IF(OR($F5="",$F5=0),"Pending",IF(ROUND($F5-$D5,2)>0,"Overpaid",IF(ROUND($F5-$D5,2)=0,"Paid","Partial")))) | K5: =IF($A5="","","#"&TRIM(SUBSTITUTE(SUBSTITUTE(SUBSTITUTE(SUBSTITUTE(SUBSTITUTE(SUBSTITUTE($A5,"-",""),"(",""),")",""),".",""),"+","")," ","")))
E6: =IF(OR($D6="",$K6=""),"",IF(COUNTIFS(Payments!$G$5:$G$2500,$K6,Payments!$C$5:$C$2500,"<>")=0,"",_xlfn.MAXIFS(Payments!$C$5:$C$2500,Payments!$G$5:$G$2500,$K6))) | F6: =IF(OR($D6="",$K6=""),"",SUMIF(Payments!$G$5:$G$2500,$K6,Payments!$D$5:$D$2500)) | G6: =IF($D6="","",ROUND($D6-IF($F6="",0,$F6),2)) | H6: =IF(OR($D6="",$K6=""),"",COUNTIF(Payments!$G$5:$G$2500,$K6)) | I6: =IF($D6="","",IF(OR($F6="",$F6=0),"Pending",IF(ROUND($F6-$D6,2)>0,"Overpaid",IF(ROUND($F6-$D6,2)=0,"Paid","Partial")))) | K6: =IF($A6="","","#"&TRIM(SUBSTITUTE(SUBSTITUTE(SUBSTITUTE(SUBSTITUTE(SUBSTITUTE(SUBSTITUTE($A6,"-",""),"(",""),")",""),".",""),"+","")," ","")))
E7: =IF(OR($D7="",$K7=""),"",IF(COUNTIFS(Payments!$G$5:$G$2500,$K7,Payments!$C$5:$C$2500,"<>")=0,"",_xlfn.MAXIFS(Payments!$C$5:$C$2500,Payments!$G$5:$G$2500,$K7))) | F7: =IF(OR($D7="",$K7=""),"",SUMIF(Payments!$G$5:$G$2500,$K7,Payments!$D$5:$D$2500)) | G7: =IF($D7="","",ROUND($D7-IF($F7="",0,$F7),2)) | H7: =IF(OR($D7="",$K7=""),"",COUNTIF(Payments!$G$5:$G$2500,$K7)) | I7: =IF($D7="","",IF(OR($F7="",$F7=0),"Pending",IF(ROUND($F7-$D7,2)>0,"Overpaid",IF(ROUND($F7-$D7,2)=0,"Paid","Partial")))) | K7: =IF($A7="","","#"&TRIM(SUBSTITUTE(SUBSTITUTE(SUBSTITUTE(SUBSTITUTE(SUBSTITUTE(SUBSTITUTE($A7,"-",""),"(",""),")",""),".",""),"+","")," ","")))
E8: =IF(OR($D8="",$K8=""),"",IF(COUNTIFS(Payments!$G$5:$G$2500,$K8,Payments!$C$5:$C$2500,"<>")=0,"",_xlfn.MAXIFS(Payments!$C$5:$C$2500,Payments!$G$5:$G$2500,$K8))) | F8: =IF(OR($D8="",$K8=""),"",SUMIF(Payments!$G$5:$G$2500,$K8,Payments!$D$5:$D$2500)) | G8: =IF($D8="","",ROUND($D8-IF($F8="",0,$F8),2)) | H8: =IF(OR($D8="",$K8=""),"",COUNTIF(Payments!$G$5:$G$2500,$K8)) | I8: =IF($D8="","",IF(OR($F8="",$F8=0),"Pending",IF(ROUND($F8-$D8,2)>0,"Overpaid",IF(ROUND($F8-$D8,2)=0,"Paid","Partial")))) | K8: =IF($A8="","","#"&TRIM(SUBSTITUTE(SUBSTITUTE(SUBSTITUTE(SUBSTITUTE(SUBSTITUTE(SUBSTITUTE($A8,"-",""),"(",""),")",""),".",""),"+","")," ","")))
E9: =IF(OR($D9="",$K9=""),"",IF(COUNTIFS(Payments!$G$5:$G$2500,$K9,Payments!$C$5:$C$2500,"<>")=0,"",_xlfn.MAXIFS(Payments!$C$5:$C$2500,Payments!$G$5:$G$2500,$K9))) | F9: =IF(OR($D9="",$K9=""),"",SUMIF(Payments!$G$5:$G$2500,$K9,Payments!$D$5:$D$2500)) | G9: =IF($D9="","",ROUND($D9-IF($F9="",0,$F9),2)) | H9: =IF(OR($D9="",$K9=""),"",COUNTIF(Payments!$G$5:$G$2500,$K9)) | I9: =IF($D9="","",IF(OR($F9="",$F9=0),"Pending",IF(ROUND($F9-$D9,2)>0,"Overpaid",IF(ROUND($F9-$D9,2)=0,"Paid","Partial")))) | K9: =IF($A9="","","#"&TRIM(SUBSTITUTE(SUBSTITUTE(SUBSTITUTE(SUBSTITUTE(SUBSTITUTE(SUBSTITUTE($A9,"-",""),"(",""),")",""),".",""),"+","")," ","")))
E10: =IF(OR($D10="",$K10=""),"",IF(COUNTIFS(Payments!$G$5:$G$2500,$K10,Payments!$C$5:$C$2500,"<>")=0,"",_xlfn.MAXIFS(Payments!$C$5:$C$2500,Payments!$G$5:$G$2500,$K10))) | F10: =IF(OR($D10="",$K10=""),"",SUMIF(Payments!$G$5:$G$2500,$K10,Payments!$D$5:$D$2500)) | G10: =IF($D10="","",ROUND($D10-IF($F10="",0,$F10),2)) | H10: =IF(OR($D10="",$K10=""),"",COUNTIF(Payments!$G$5:$G$2500,$K10)) | I10: =IF($D10="","",IF(OR($F10="",$F10=0),"Pending",IF(ROUND($F10-$D10,2)>0,"Overpaid",IF(ROUND($F10-$D10,2)=0,"Paid","Partial")))) | K10: =IF($A10="","","#"&TRIM(SUBSTITUTE(SUBSTITUTE(SUBSTITUTE(SUBSTITUTE(SUBSTITUTE(SUBSTITUTE($A10,"-",""),"(",""),")",""),".",""),"+","")," ","")))
E11: =IF(OR($D11="",$K11=""),"",IF(COUNTIFS(Payments!$G$5:$G$2500,$K11,Payments!$C$5:$C$2500,"<>")=0,"",_xlfn.MAXIFS(Payments!$C$5:$C$2500,Payments!$G$5:$G$2500,$K11))) | F11: =IF(OR($D11="",$K11=""),"",SUMIF(Payments!$G$5:$G$2500,$K11,Payments!$D$5:$D$2500)) | G11: =IF($D11="","",ROUND($D11-IF($F11="",0,$F11),2)) | H11: =IF(OR($D11="",$K11=""),"",COUNTIF(Payments!$G$5:$G$2500,$K11)) | I11: =IF($D11="","",IF(OR($F11="",$F11=0),"Pending",IF(ROUND($F11-$D11,2)>0,"Overpaid",IF(ROUND($F11-$D11,2)=0,"Paid","Partial")))) | K11: =IF($A11="","","#"&TRIM(SUBSTITUTE(SUBSTITUTE(SUBSTITUTE(SUBSTITUTE(SUBSTITUTE(SUBSTITUTE($A11,"-",""),"(",""),")",""),".",""),"+","")," ","")))
E12: =IF(OR($D12="",$K12=""),"",IF(COUNTIFS(Payments!$G$5:$G$2500,$K12,Payments!$C$5:$C$2500,"<>")=0,"",_xlfn.MAXIFS(Payments!$C$5:$C$2500,Payments!$G$5:$G$2500,$K12))) | F12: =IF(OR($D12="",$K12=""),"",SUMIF(Payments!$G$5:$G$2500,$K12,Payments!$D$5:$D$2500)) | G12: =IF($D12="","",ROUND($D12-IF($F12="",0,$F12),2)) | H12: =IF(OR($D12="",$K12=""),"",COUNTIF(Payments!$G$5:$G$2500,$K12)) | I12: =IF($D12="","",IF(OR($F12="",$F12=0),"Pending",IF(ROUND($F12-$D12,2)>0,"Overpaid",IF(ROUND($F12-$D12,2)=0,"Paid","Partial")))) | K12: =IF($A12="","","#"&TRIM(SUBSTITUTE(SUBSTITUTE(SUBSTITUTE(SUBSTITUTE(SUBSTITUTE(SUBSTITUTE($A12,"-",""),"(",""),")",""),".",""),"+","")," ","")))
E13: =IF(OR($D13="",$K13=""),"",IF(COUNTIFS(Payments!$G$5:$G$2500,$K13,Payments!$C$5:$C$2500,"<>")=0,"",_xlfn.MAXIFS(Payments!$C$5:$C$2500,Payments!$G$5:$G$2500,$K13))) | F13: =IF(OR($D13="",$K13=""),"",SUMIF(Payments!$G$5:$G$2500,$K13,Payments!$D$5:$D$2500)) | G13: =IF($D13="","",ROUND($D13-IF($F13="",0,$F13),2)) | H13: =IF(OR($D13="",$K13=""),"",COUNTIF(Payments!$G$5:$G$2500,$K13)) | I13: =IF($D13="","",IF(OR($F13="",$F13=0),"Pending",IF(ROUND($F13-$D13,2)>0,"Overpaid",IF(ROUND($F13-$D13,2)=0,"Paid","Partial")))) | K13: =IF($A13="","","#"&TRIM(SUBSTITUTE(SUBSTITUTE(SUBSTITUTE(SUBSTITUTE(SUBSTITUTE(SUBSTITUTE($A13,"-",""),"(",""),")",""),".",""),"+","")," ","")))
E14: =IF(OR($D14="",$K14=""),"",IF(COUNTIFS(Payments!$G$5:$G$2500,$K14,Payments!$C$5:$C$2500,"<>")=0,"",_xlfn.MAXIFS(Payments!$C$5:$C$2500,Payments!$G$5:$G$2500,$K14))) | F14: =IF(OR($D14="",$K14=""),"",SUMIF(Payments!$G$5:$G$2500,$K14,Payments!$D$5:$D$2500)) | G14: =IF($D14="","",ROUND($D14-IF($F14="",0,$F14),2)) | H14: =IF(OR($D14="",$K14=""),"",COUNTIF(Payments!$G$5:$G$2500,$K14)) | I14: =IF($D14="","",IF(OR($F14="",$F14=0),"Pending",IF(ROUND($F14-$D14,2)>0,"Overpaid",IF(ROUND($F14-$D14,2)=0,"Paid","Partial")))) | K14: =IF($A14="","","#"&TRIM(SUBSTITUTE(SUBSTITUTE(SUBSTITUTE(SUBSTITUTE(SUBSTITUTE(SUBSTITUTE($A14,"-",""),"(",""),")",""),".",""),"+","")," ","")))
E15: =IF(OR($D15="",$K15=""),"",IF(COUNTIFS(Payments!$G$5:$G$2500,$K15,Payments!$C$5:$C$2500,"<>")=0,"",_xlfn.MAXIFS(Payments!$C$5:$C$2500,Payments!$G$5:$G$2500,$K15))) | F15: =IF(OR($D15="",$K15=""),"",SUMIF(Payments!$G$5:$G$2500,$K15,Payments!$D$5:$D$2500)) | G15: =IF($D15="","",ROUND($D15-IF($F15="",0,$F15),2)) | H15: =IF(OR($D15="",$K15=""),"",COUNTIF(Payments!$G$5:$G$2500,$K15)) | I15: =IF($D15="","",IF(OR($F15="",$F15=0),"Pending",IF(ROUND($F15-$D15,2)>0,"Overpaid",IF(ROUND($F15-$D15,2)=0,"Paid","Partial")))) | K15: =IF($A15="","","#"&TRIM(SUBSTITUTE(SUBSTITUTE(SUBSTITUTE(SUBSTITUTE(SUBSTITUTE(SUBSTITUTE($A15,"-",""),"(",""),")",""),".",""),"+","")," ","")))
E16: =IF(OR($D16="",$K16=""),"",IF(COUNTIFS(Payments!$G$5:$G$2500,$K16,Payments!$C$5:$C$2500,"<>")=0,"",_xlfn.MAXIFS(Payments!$C$5:$C$2500,Payments!$G$5:$G$2500,$K16))) | F16: =IF(OR($D16="",$K16=""),"",SUMIF(Payments!$G$5:$G$2500,$K16,Payments!$D$5:$D$2500)) | G16: =IF($D16="","",ROUND($D16-IF($F16="",0,$F16),2)) | H16: =IF(OR($D16="",$K16=""),"",COUNTIF(Payments!$G$5:$G$2500,$K16)) | I16: =IF($D16="","",IF(OR($F16="",$F16=0),"Pending",IF(ROUND($F16-$D16,2)>0,"Overpaid",IF(ROUND($F16-$D16,2)=0,"Paid","Partial")))) | K16: =IF($A16="","","#"&TRIM(SUBSTITUTE(SUBSTITUTE(SUBSTITUTE(SUBSTITUTE(SUBSTITUTE(SUBSTITUTE($A16,"-",""),"(",""),")",""),".",""),"+","")," ","")))
... E2000: =IF(OR($D2000="",$K2000=""),"",IF(COUNTIFS(Payments!$G$5:$G$2500,$K2000,Payments!$C$5:$C$2500,"<>")=0,"",_xlfn.MAXIFS(Payments!$C$5:$C$2500,Payments!$G$5:$G$2500,$K2000))) | F2000: =IF(OR($D2000="",$K2000=""),"",SUMIF(Payments!$G$5:$G$2500,$K2000,Payments!$D$5:$D$2500)) | G2000: =IF($D2000="","",ROUND($D2000-IF($F2000="",0,$F2000),2)) | H2000: =IF(OR($D2000="",$K2000=""),"",COUNTIF(Payments!$G$5:$G$2500,$K2000)) | I2000: =IF($D2000="","",IF(OR($F2000="",$F2000=0),"Pending",IF(ROUND($F2000-$D2000,2)>0,"Overpaid",IF(ROUND($F2000-$D2000,2)=0,"Paid","Partial")))) | K2000: =IF($A2000="","","#"&TRIM(SUBSTITUTE(SUBSTITUTE(SUBSTITUTE(SUBSTITUTE(SUBSTITUTE(SUBSTITUTE($A2000,"-",""),"(",""),")",""),".",""),"+","")," ","")))

Sheet Payments
A1: Masjid Fundraiser — Payments Received Log
A2: One row per payment received — a donor paying in installments gets one row per installment. Hover a column heading for an example. Just type on the first empty row; the list grows on its own.
B3: Totals → | C3: =COUNTIF($D$5:$D$2500,">0")&" payments" -> 0 payments | D3: =SUM($D$5:$D$2500) -> 0
A4: Phone Number (Donor ID) | B4: Donor Name | C4: Date Received | D4: Amount Received ($) | E4: Payment Method | F4: Notes | G4: Match Key
B5: =IF($A5="","",IFERROR(IF(INDEX(Pledges!$D$5:$D$2500,MATCH($G5,Pledges!$K$5:$K$2500,0))="","⚠ no amount on Pledges",IF(INDEX(Pledges!$B$5:$B$2500,MATCH($G5,Pledges!$K$5:$K$2500,0))="","",INDEX(Pledges!$B$5:$B$2500,MATCH($G5,Pledges!$K$5:$K$2500,0)))),"⚠ phone not in Pledges")) | G5: =IF($A5="","","#"&TRIM(SUBSTITUTE(SUBSTITUTE(SUBSTITUTE(SUBSTITUTE(SUBSTITUTE(SUBSTITUTE($A5,"-",""),"(",""),")",""),".",""),"+","")," ","")))
B6: =IF($A6="","",IFERROR(IF(INDEX(Pledges!$D$5:$D$2500,MATCH($G6,Pledges!$K$5:$K$2500,0))="","⚠ no amount on Pledges",IF(INDEX(Pledges!$B$5:$B$2500,MATCH($G6,Pledges!$K$5:$K$2500,0))="","",INDEX(Pledges!$B$5:$B$2500,MATCH($G6,Pledges!$K$5:$K$2500,0)))),"⚠ phone not in Pledges")) | G6: =IF($A6="","","#"&TRIM(SUBSTITUTE(SUBSTITUTE(SUBSTITUTE(SUBSTITUTE(SUBSTITUTE(SUBSTITUTE($A6,"-",""),"(",""),")",""),".",""),"+","")," ","")))
B7: =IF($A7="","",IFERROR(IF(INDEX(Pledges!$D$5:$D$2500,MATCH($G7,Pledges!$K$5:$K$2500,0))="","⚠ no amount on Pledges",IF(INDEX(Pledges!$B$5:$B$2500,MATCH($G7,Pledges!$K$5:$K$2500,0))="","",INDEX(Pledges!$B$5:$B$2500,MATCH($G7,Pledges!$K$5:$K$2500,0)))),"⚠ phone not in Pledges")) | G7: =IF($A7="","","#"&TRIM(SUBSTITUTE(SUBSTITUTE(SUBSTITUTE(SUBSTITUTE(SUBSTITUTE(SUBSTITUTE($A7,"-",""),"(",""),")",""),".",""),"+","")," ","")))
B8: =IF($A8="","",IFERROR(IF(INDEX(Pledges!$D$5:$D$2500,MATCH($G8,Pledges!$K$5:$K$2500,0))="","⚠ no amount on Pledges",IF(INDEX(Pledges!$B$5:$B$2500,MATCH($G8,Pledges!$K$5:$K$2500,0))="","",INDEX(Pledges!$B$5:$B$2500,MATCH($G8,Pledges!$K$5:$K$2500,0)))),"⚠ phone not in Pledges")) | G8: =IF($A8="","","#"&TRIM(SUBSTITUTE(SUBSTITUTE(SUBSTITUTE(SUBSTITUTE(SUBSTITUTE(SUBSTITUTE($A8,"-",""),"(",""),")",""),".",""),"+","")," ","")))
B9: =IF($A9="","",IFERROR(IF(INDEX(Pledges!$D$5:$D$2500,MATCH($G9,Pledges!$K$5:$K$2500,0))="","⚠ no amount on Pledges",IF(INDEX(Pledges!$B$5:$B$2500,MATCH($G9,Pledges!$K$5:$K$2500,0))="","",INDEX(Pledges!$B$5:$B$2500,MATCH($G9,Pledges!$K$5:$K$2500,0)))),"⚠ phone not in Pledges")) | G9: =IF($A9="","","#"&TRIM(SUBSTITUTE(SUBSTITUTE(SUBSTITUTE(SUBSTITUTE(SUBSTITUTE(SUBSTITUTE($A9,"-",""),"(",""),")",""),".",""),"+","")," ","")))
B10: =IF($A10="","",IFERROR(IF(INDEX(Pledges!$D$5:$D$2500,MATCH($G10,Pledges!$K$5:$K$2500,0))="","⚠ no amount on Pledges",IF(INDEX(Pledges!$B$5:$B$2500,MATCH($G10,Pledges!$K$5:$K$2500,0))="","",INDEX(Pledges!$B$5:$B$2500,MATCH($G10,Pledges!$K$5:$K$2500,0)))),"⚠ phone not in Pledges")) | G10: =IF($A10="","","#"&TRIM(SUBSTITUTE(SUBSTITUTE(SUBSTITUTE(SUBSTITUTE(SUBSTITUTE(SUBSTITUTE($A10,"-",""),"(",""),")",""),".",""),"+","")," ","")))
B11: =IF($A11="","",IFERROR(IF(INDEX(Pledges!$D$5:$D$2500,MATCH($G11,Pledges!$K$5:$K$2500,0))="","⚠ no amount on Pledges",IF(INDEX(Pledges!$B$5:$B$2500,MATCH($G11,Pledges!$K$5:$K$2500,0))="","",INDEX(Pledges!$B$5:$B$2500,MATCH($G11,Pledges!$K$5:$K$2500,0)))),"⚠ phone not in Pledges")) | G11: =IF($A11="","","#"&TRIM(SUBSTITUTE(SUBSTITUTE(SUBSTITUTE(SUBSTITUTE(SUBSTITUTE(SUBSTITUTE($A11,"-",""),"(",""),")",""),".",""),"+","")," ","")))
B12: =IF($A12="","",IFERROR(IF(INDEX(Pledges!$D$5:$D$2500,MATCH($G12,Pledges!$K$5:$K$2500,0))="","⚠ no amount on Pledges",IF(INDEX(Pledges!$B$5:$B$2500,MATCH($G12,Pledges!$K$5:$K$2500,0))="","",INDEX(Pledges!$B$5:$B$2500,MATCH($G12,Pledges!$K$5:$K$2500,0)))),"⚠ phone not in Pledges")) | G12: =IF($A12="","","#"&TRIM(SUBSTITUTE(SUBSTITUTE(SUBSTITUTE(SUBSTITUTE(SUBSTITUTE(SUBSTITUTE($A12,"-",""),"(",""),")",""),".",""),"+","")," ","")))
B13: =IF($A13="","",IFERROR(IF(INDEX(Pledges!$D$5:$D$2500,MATCH($G13,Pledges!$K$5:$K$2500,0))="","⚠ no amount on Pledges",IF(INDEX(Pledges!$B$5:$B$2500,MATCH($G13,Pledges!$K$5:$K$2500,0))="","",INDEX(Pledges!$B$5:$B$2500,MATCH($G13,Pledges!$K$5:$K$2500,0)))),"⚠ phone not in Pledges")) | G13: =IF($A13="","","#"&TRIM(SUBSTITUTE(SUBSTITUTE(SUBSTITUTE(SUBSTITUTE(SUBSTITUTE(SUBSTITUTE($A13,"-",""),"(",""),")",""),".",""),"+","")," ","")))
B14: =IF($A14="","",IFERROR(IF(INDEX(Pledges!$D$5:$D$2500,MATCH($G14,Pledges!$K$5:$K$2500,0))="","⚠ no amount on Pledges",IF(INDEX(Pledges!$B$5:$B$2500,MATCH($G14,Pledges!$K$5:$K$2500,0))="","",INDEX(Pledges!$B$5:$B$2500,MATCH($G14,Pledges!$K$5:$K$2500,0)))),"⚠ phone not in Pledges")) | G14: =IF($A14="","","#"&TRIM(SUBSTITUTE(SUBSTITUTE(SUBSTITUTE(SUBSTITUTE(SUBSTITUTE(SUBSTITUTE($A14,"-",""),"(",""),")",""),".",""),"+","")," ","")))
B15: =IF($A15="","",IFERROR(IF(INDEX(Pledges!$D$5:$D$2500,MATCH($G15,Pledges!$K$5:$K$2500,0))="","⚠ no amount on Pledges",IF(INDEX(Pledges!$B$5:$B$2500,MATCH($G15,Pledges!$K$5:$K$2500,0))="","",INDEX(Pledges!$B$5:$B$2500,MATCH($G15,Pledges!$K$5:$K$2500,0)))),"⚠ phone not in Pledges")) | G15: =IF($A15="","","#"&TRIM(SUBSTITUTE(SUBSTITUTE(SUBSTITUTE(SUBSTITUTE(SUBSTITUTE(SUBSTITUTE($A15,"-",""),"(",""),")",""),".",""),"+","")," ","")))
B16: =IF($A16="","",IFERROR(IF(INDEX(Pledges!$D$5:$D$2500,MATCH($G16,Pledges!$K$5:$K$2500,0))="","⚠ no amount on Pledges",IF(INDEX(Pledges!$B$5:$B$2500,MATCH($G16,Pledges!$K$5:$K$2500,0))="","",INDEX(Pledges!$B$5:$B$2500,MATCH($G16,Pledges!$K$5:$K$2500,0)))),"⚠ phone not in Pledges")) | G16: =IF($A16="","","#"&TRIM(SUBSTITUTE(SUBSTITUTE(SUBSTITUTE(SUBSTITUTE(SUBSTITUTE(SUBSTITUTE($A16,"-",""),"(",""),")",""),".",""),"+","")," ","")))
... B2000: =IF($A2000="","",IFERROR(IF(INDEX(Pledges!$D$5:$D$2500,MATCH($G2000,Pledges!$K$5:$K$2500,0))="","⚠ no amount on Pledges",IF(INDEX(Pledges!$B$5:$B$2500,MATCH($G2000,Pledges!$K$5:$K$2500,0))="","",INDEX(Pledges!$B$5:$B$2500,MATCH($G2000,Pledges!$K$5:$K$2500,0)))),"⚠ phone not in Pledges")) | G2000: =IF($A2000="","","#"&TRIM(SUBSTITUTE(SUBSTITUTE(SUBSTITUTE(SUBSTITUTE(SUBSTITUTE(SUBSTITUTE($A2000,"-",""),"(",""),")",""),".",""),"+","")," ","")))

Sheet Summary
A1: Fundraiser Summary
A2: Updates automatically from the Pledges and Payments tabs.
A4: Fundraiser Goal ($) | B4: 10000
A5: Total Pledged ($) | B5: =SUM(Pledges!$D$5:$D$2500)
A6: Total Received ($) | B6: =SUM(Pledges!$F$5:$F$2500)
A7: Total Balance Outstanding ($) | B7: =SUMIF(Pledges!$G$5:$G$2500,">0")
A8: Total Overpaid / Credit ($) | B8: =ABS(SUMIF(Pledges!$G$5:$G$2500,"<0"))
A9: Number of Donors (pledged) | B9: =COUNTIF(Pledges!$D$5:$D$2500,">0")
A10: Number Fully Paid | B10: =COUNTIF(Pledges!$I$5:$I$2500,"Paid")
A11: Number Partial | B11: =COUNTIF(Pledges!$I$5:$I$2500,"Partial")
A12: Number Pending | B12: =COUNTIF(Pledges!$I$5:$I$2500,"Pending")
A13: Number Overpaid | B13: =COUNTIF(Pledges!$I$5:$I$2500,"Overpaid")
A14: % of Goal Received | B14: =IFERROR(B6/B4,0)
A15: Payments Logged ($) | B15: =SUM(Payments!$D$5:$D$2500)
A16: Unmatched Payments ($) | B16: =B15-B6
A17: Legend: yellow cell = entry. Green figures are pulled from another tab. Formulas use plain cell ranges so the file also works in Google Sheets.
A19: Data Health
A20: Every figure below should read 0. Anything higher needs a look.
A21: Payments not matched to a pledge | B21: =COUNTIF(Payments!$B$5:$B$2500,"⚠*")
A22: Donors listed more than once | B22: =SUMPRODUCT((Pledges!$K$5:$K$2500<>"")*(COUNTIF(Pledges!$K$5:$K$2500,Pledges!$K$5:$K$2500)>1))
A23: Pledges missing a phone number | B23: =COUNTIFS(Pledges!$D$5:$D$2500,">0",Pledges!$A$5:$A$2500,"")
A24: Payments missing a date or amount | B24: =SUMPRODUCT((Payments!$A$5:$A$2500<>"")*((Payments!$C$5:$C$2500="")+(Payments!$D$5:$D$2500="")>0))
A25: Payments dated in the future | B25: =SUMPRODUCT((Payments!$C$5:$C$2500<>"")*(Payments!$C$5:$C$2500>TODAY()))
A26: Donors whose payments predate their pledge | B26: =SUMPRODUCT((Pledges!$E$5:$E$2500<>"")*(Pledges!$E$5:$E$2500<Pledges!$C$5:$C$2500))
A27: Red and amber rows on the Pledges/Payments tabs mark the first, second and fifth checks. For the rest, filter those tabs for blank cells or compare the dates.
A29: Collected by Payment Method
A30: Cash | B30: =SUMIF(Payments!$E$5:$E$2500,"Cash",Payments!$D$5:$D$2500)
A31: Bank Transfer | B31: =SUMIF(Payments!$E$5:$E$2500,"Bank Transfer",Payments!$D$5:$D$2500)
A32: Card | B32: =SUMIF(Payments!$E$5:$E$2500,"Card",Payments!$D$5:$D$2500)
A33: Check | B33: =SUMIF(Payments!$E$5:$E$2500,"Check",Payments!$D$5:$D$2500)
A34: Online | B34: =SUMIF(Payments!$E$5:$E$2500,"Online",Payments!$D$5:$D$2500)
A35: Other | B35: =SUMIF(Payments!$E$5:$E$2500,"Other",Payments!$D$5:$D$2500)
A36: No method recorded | B36: =SUMIFS(Payments!$D$5:$D$2500,Payments!$E$5:$E$2500,"")
A37: Total (should match Payments Logged) | B37: =SUM(B30:B36)
A38: Donor Lookup
A39: Enter a phone number below to pull that donor's status. Dashes and spaces do not matter.
A41: Phone Number | D41: =IF($B$41="","","#"&TRIM(SUBSTITUTE(SUBSTITUTE(SUBSTITUTE(SUBSTITUTE(SUBSTITUTE(SUBSTITUTE($B$41,"-",""),"(",""),")",""),".",""),"+","")," ","")))
A42: Donor Name | B42: =IF($B$41="","",IFERROR(IF(INDEX(Pledges!$B$5:$B$2500,MATCH($D$41,Pledges!$K$5:$K$2500,0))="","",INDEX(Pledges!$B$5:$B$2500,MATCH($D$41,Pledges!$K$5:$K$2500,0))),"Not found"))
A43: Date Pledged | B43: =IF($B$41="","",IFERROR(IF(INDEX(Pledges!$C$5:$C$2500,MATCH($D$41,Pledges!$K$5:$K$2500,0))="","",INDEX(Pledges!$C$5:$C$2500,MATCH($D$41,Pledges!$K$5:$K$2500,0))),"Not found"))
A44: Amount Pledged ($) | B44: =IF($B$41="","",IFERROR(IF(INDEX(Pledges!$D$5:$D$2500,MATCH($D$41,Pledges!$K$5:$K$2500,0))="","",INDEX(Pledges!$D$5:$D$2500,MATCH($D$41,Pledges!$K$5:$K$2500,0))),"Not found"))
...
